Workbook

Sheet Employee
A1: Important Points | M1: Evaluation
A2: 1 | B2: Create 40 Employee which should be bifurcated between 4 location MUMBAI,DELHI and CHENNAI and Bangalore
A3: 2 | B3: Make sure that eligibility for PF and ESI to be checked
A4: 3 | B4: Professional tax to be callculated in CTC based on location
A6: Code | B6: Name | C6: Birth Date | D6: Join Date | E6: Department | F6: Designation | G6: Location | H6: PF | I6: ESI | J6: PT State | K6: Gross Salary | M6: Target | N6: Achived
A7: 1 | B7: Name 1 | C7: 33329 | D7: 45078 | E7: HR | F7: HR | G7: MUMBAI | H7: Y | I7: Y | J7: MAHARASHTRA | K7: 8000 | M7: =COUNTA(A7:K7) -> 11 | N7: 11
A8: 2 | B8: Name 2 | C8: 33330 | D8: 45079 | E8: SALES | F8: Sales Man | G8: MUMBAI | H8: N | I8: Y | J8: MAHARASHTRA | K8: 10000 | M8: =COUNTA(A8:K8) -> 11 | N8: 11
A9: 3 | B9: Name 3 | C9: 33331 | D9: 45080 | E9: PRODUCTION | F9: Worker | G9: MUMBAI | H9: Y | I9: Y | J9: MAHARASHTRA | K9: 12000 | M9: =COUNTA(A9:K9) -> 11 | N9: 11
A10: 4 | B10: Name 4 | C10: 33332 | D10: 45081 | E10: SALES | F10: Sales head | G10: MUMBAI | H10: N | I10: Y | J10: MAHARASHTRA | K10: 15000 | M10: =COUNTA(A10:K10) -> 11 | N10: 11
A11: 5 | B11: Name 5 | C11: 33333 | D11: 45082 | E11: OPERATIONS | F11: General Manager | G11: MUMBAI | H11: Y | I11: Y | J11: MAHARASHTRA | K11: 20000 | M11: =COUNTA(A11:K11) -> 11 | N11: 11
A12: 6 | B12: Name 6 | C12: 33334 | D12: 45083 | E12: OPERATIONS | F12: Support Manager | G12: MUMBAI | H12: N | I12: Y | J12: MAHARASHTRA | K12: =K11+1000 -> 21000 | M12: =COUNTA(A12:K12) -> 11 | N12: 11
A13: 7 | B13: Name 7 | C13: 33335 | D13: 45084 | E13: HR | F13: VP HR | G13: MUMBAI | H13: Y | I13: N | J13: MAHARASHTRA | K13: 35000 | M13: =COUNTA(A13:K13) -> 11 | N13: 11
A14: 8 | B14: Name 8 | C14: 33336 | D14: 45085 | E14: FINANCE | F14: Fiannce Head | G14: MUMBAI | H14: N | I14: N | J14: MAHARASHTRA | K14: 8000 | M14: =COUNTA(A14:K14) -> 11 | N14: 11
A15: 9 | B15: Name 9 | C15: 33337 | D15: 45086 | E15: HR | F15: Head HR | G15: MUMBAI | H15: Y | I15: N | J15: MAHARASHTRA | K15: 16500 | M15: =COUNTA(A15:K15) -> 11 | N15: 11
A16: 10 | B16: Name 10 | C16: 33338 | D16: 45087 | E16: MANAGEMENT | F16: Director | G16: MUMBAI | H16: N | I16: N | J16: MAHARASHTRA | K16: 40000 | M16: =COUNTA(A16:K16) -> 11 | N16: 11
A17: 11 | B17: Name 11 | C17: 33339 | D17: 45088 | E17: HR | F17: HR | G17: DELHI | H17: Y | I17: Y | J17: NEW DELHI | K17: 8000 | M17: =COUNTA(A17:K17) -> 11 | N17: 11
A18: 12 | B18: Name 12 | C18: 33340 | D18: 45089 | E18: SALES | F18: Sales Man | G18: DELHI | H18: N | I18: Y | J18: NEW DELHI | K18: 10000 | M18: =COUNTA(A18:K18) -> 11 | N18: 11
A19: 13 | B19: Name 13 | C19: 33341 | D19: 45090 | E19: PRODUCTION | F19: Worker | G19: DELHI | H19: Y | I19: Y | J19: NEW DELHI | K19: 12000 | M19: =COUNTA(A19:K19) -> 11 | N19: 11
A20: 14 | B20: Name 14 | C20: 33342 | D20: 45091 | E20: SALES | F20: Sales head | G20: DELHI | H20: N | I20: Y | J20: NEW DELHI | K20: 15000 | M20: =COUNTA(A20:K20) -> 11 | N20: 11
A21: 15 | B21: Name 15 | C21: 33343 | D21: 45092 | E21: OPERATIONS | F21: General Manager | G21: DELHI | H21: Y | I21: Y | J21: NEW DELHI | K21: 20000 | M21: =COUNTA(A21:K21) -> 11 | N21: 11
A22: 16 | B22: Name 16 | C22: 33344 | D22: 45093 | E22: OPERATIONS | F22: Support Manager | G22: DELHI | H22: N | I22: Y | J22: NEW DELHI | K22: =K21+1000 -> 21000 | M22: =COUNTA(A22:K22) -> 11 | N22: 11
A23: 17 | B23: Name 17 | C23: 33345 | D23: 45094 | E23: HR | F23: VP HR | G23: DELHI | H23: Y | I23: N | J23: NEW DELHI | K23: 35000 | M23: =COUNTA(A23:K23) -> 11 | N23: 11
A24: 18 | B24: Name 18 | C24: 33346 | D24: 45095 | E24: FINANCE | F24: Fiannce Head | G24: DELHI | H24: N | I24: N | J24: NEW DELHI | K24: 8000 | M24: =COUNTA(A24:K24) -> 11 | N24: 11
A25: 19 | B25: Name 19 | C25: 33347 | D25: 45096 | E25: HR | F25: Head HR | G25: DELHI | H25: Y | I25: N | J25: NEW DELHI | K25: 16500 | M25: =COUNTA(A25:K25) -> 11 | N25: 11
A26: 20 | B26: Name 20 | C26: 33348 | D26: 45097 | E26: MANAGEMENT | F26: Director | G26: DELHI | H26: N | I26: N | J26: NEW DELHI | K26: 40000 | M26: =COUNTA(A26:K26) -> 11 | N26: 11
A27: 21 | B27: Name 21 | C27: 33349 | D27: 45098 | E27: HR | F27: HR | G27: CHENNAI | H27: Y | I27: Y | J27: TAMILNADU | K27: 8000 | M27: =COUNTA(A27:K27) -> 11 | N27: 11
A28: 22 | B28: Name 22 | C28: 33350 | D28: 45099 | E28: SALES | F28: Sales Man | G28: CHENNAI | H28: N | I28: Y | J28: TAMILNADU | K28: 10000 | M28: =COUNTA(A28:K28) -> 11 | N28: 11
A29: 23 | B29: Name 23 | C29: 33351 | D29: 45100 | E29: PRODUCTION | F29: Worker | G29: CHENNAI | H29: Y | I29: Y | J29: TAMILNADU | K29: 12000 | M29: =COUNTA(A29:K29) -> 11 | N29: 11
A30: 24 | B30: Name 24 | C30: 33352 | D30: 45101 | E30: SALES | F30: Sales head | G30: CHENNAI | H30: N | I30: Y | J30: TAMILNADU | K30: 15000 | M30: =COUNTA(A30:K30) -> 11 | N30: 11
A31: 25 | B31: Name 25 | C31: 33353 | D31: 45102 | E31: OPERATIONS | F31: General Manager | G31: CHENNAI | H31: Y | I31: Y | J31: TAMILNADU | K31: 20000 | M31: =COUNTA(A31:K31) -> 11 | N31: 11
A32: 26 | B32: Name 26 | C32: 33354 | D32: 45103 | E32: OPERATIONS | F32: Support Manager | G32: CHENNAI | H32: N | I32: Y | J32: TAMILNADU | K32: =K31+1000 -> 21000 | M32: =COUNTA(A32:K32) -> 11 | N32: 11
A33: 27 | B33: Name 27 | C33: 33355 | D33: 45104 | E33: HR | F33: VP HR | G33: CHENNAI | H33: Y | I33: N | J33: TAMILNADU | K33: 35000 | M33: =COUNTA(A33:K33) -> 11 | N33: 11
A34: 28 | B34: Name 28 | C34: 33356 | D34: 45105 | E34: FINANCE | F34: Fiannce Head | G34: CHENNAI | H34: N | I34: N | J34: TAMILNADU | K34: 8000 | M34: =COUNTA(A34:K34) -> 11 | N34: 11
A35: 29 | B35: Name 29 | C35: 33357 | D35: 45106 | E35: HR | F35: Head HR | G35: CHENNAI | H35: Y | I35: N | J35: TAMILNADU | K35: 16500 | M35: =COUNTA(A35:K35) -> 11 | N35: 11
A36: 30 | B36: Name 30 | C36: 33358 | D36: 45107 | E36: MANAGEMENT | F36: Director | G36: CHENNAI | H36: N | I36: N | J36: TAMILNADU | K36: 40000 | M36: =COUNTA(A36:K36) -> 11 | N36: 11
A37: 31 | B37: Name 31 | C37: 33359 | D37: 45108 | E37: HR | F37: HR | G37: BANGALORe | H37: Y | I37: N | J37: KARNATAKA | K37: 8000 | M37: =COUNTA(A37:K37) -> 11 | N37: 11
A38: 32 | B38: Name 32 | C38: 33360 | D38: 45109 | E38: SALES | F38: Sales Man | G38: BANGALORe | H38: N | I38: N | J38: KARNATAKA | K38: 10000 | M38: =COUNTA(A38:K38) -> 11 | N38: 11
A39: 33 | B39: Name 33 | C39: 33361 | D39: 45110 | E39: PRODUCTION | F39: Worker | G39: BANGALORe | H39: Y | I39: N | J39: KARNATAKA | K39: 12000 | M39: =COUNTA(A39:K39) -> 11 | N39: 11
A40: 34 | B40: Name 34 | C40: 33362 | D40: 45111 | E40: SALES | F40: Sales head | G40: BANGALORe | H40: N | I40: N | J40: KARNATAKA | K40: 15000 | M40: =COUNTA(A40:K40) -> 11 | N40: 11
A41: 35 | B41: Name 35 | C41: 33363 | D41: 45112 | E41: OPERATIONS | F41: General Manager | G41: BANGALORe | H41: Y | I41: N | J41: KARNATAKA | K41: 20000 | M41: =COUNTA(A41:K41) -> 11 | N41: 11
...

Sheet Attendance Configuration
H1: Evaluation
H2: Target | I2: Achived
B3: Allocation base | C3: Mumbai | D3: Delhi | E3: Chennai | F3: Bangalore | H3: =COUNTA(C3:F3) -> 4 | I3: 4
B4: Shift | C4: 10:00 to 18:00 | D4: 14:00 to 22:00 | E4: 22:00 to 06:00 | F4: 9:00 to 18:00 | H4: =COUNTA(C4:F4) -> 4 | I4: 4
B5: In Grace | C5: 5 Min | D5: 10 Min | E5: NA | F5: NA | H5: =COUNTA(C5:F5) -> 4 | I5: 4
B6: Break | C6: To be deducted | D6: To be deducted | E6: NA | F6: NA | H6: =COUNTA(C6:F6) -> 4 | I6: 4
B7: Late policy | C7: Allowed 20 min for 2 time after words every late 0.5 to be deducted | D7: To be mark half day if employee come late by 2 hours onwards | E7: Allowed 30 min for 2 time after words every late 0.5 to be deducted on every 3rd late | F7: To be mark absent day if employee come late by 2 hours onwards | H7: =COUNTA(C7:F7) -> 4 | I7: 1
B8: Early Policy | C8: NA | D8: NA | E8: Allowed 5 min for 2 time | F8: Allowed 2 time afterwords 0.5 deducted o every early going | H8: =COUNTA(C8:F8) -> 4 | I8: 0.5
B9: OT on Non working Day | C9: Yes | D9: No | E9: No | F9: Yes | H9: =COUNTA(C9:F9) -> 4 | I9: 4
B10: Min | C10: 60 | D10: 90 | E10: 90 | F10: 120 | H10: =COUNTA(C10:F10) -> 4 | I10: 4
B11: Max | C11: 240 | D11: 500 | E11: 500 | F11: 600 | H11: =COUNTA(C11:F11) -> 4 | I11: 4
B12: OT on WD | C12: No | D12: Yes | E12: Yes | F12: No | H12: =COUNTA(C12:F12) -> 4 | I12: 4
B13: Min | C13: 90 | D13: 60 | E13: 120 | F13: 90 | H13: =COUNTA(C13:F13) -> 4 | I13: 4
B14: Max | C14: 500 | D14: 240 | E14: 600 | F14: 500 | H14: =COUNTA(C14:F14) -> 4 | I14: 4
B15: WD policy | C15: Minute base | D15: % base | E15: Minute base | F15: % base | H15: =COUNTA(C15:F15) -> 4 | I15: 3
B16: Full Day Requiment | C16: Above to Half Day limit | D16: Above to Half Day limit | E16: Above to Half Day limit | F16: Above to Half Day limit | H16: =COUNTA(C16:F16) -> 4 | I16: 3
B17: HD Requirment | C17: Between 121 to 359 | D17: Between 10% to 75% | E17: Upto 300 (Late early to be checked) | F17: Between 6 to 70% | H17: =COUNTA(C17:F17) -> 4 | I17: 2.5
B18: Absent | C18: Upto 120 | D18: Upto 10% | E18: NA | F18: Upto 5% | H18: =COUNTA(C18:F18) -> 4 | I18: 3
B19: Comman Holidays | C19: 45519 | D19: 45519 | E19: 45519 | F19: 45519 | H19: =COUNTA(C19:F19) -> 4 | I19: 4
B20: Comman Holidays | C20: 45683 | D20: 45683 | E20: 45683 | F20: 45683 | H20: =COUNTA(C20:F20) -> 4 | I20: 4
B21: Week off Assignment | C21: Saturday and Sunday | D21: Wednesday every 2 and 4th | E21: Sunday | F21: Saturday and Sunday | H21: =COUNTA(C21:F21) -> 4 | I21: 0 | K21: Calandar not assigned category wise
H22: =SUM(H3:H21) -> 76 | I22: =SUM(I3:I21) -> 61
B23: Important Notes : Policy and shift to be assigned employee category wise

Sheet Leave Configuration
I1: Evaluation
I2: Target | J2: Achived
B3: Allocation | C3: Details | D3: Mumbai location | E3: Delhi | F3: Chennai | G3: Bangalore | I3: =COUNTA(D3:G3) -> 4 | J3: 4
B4: CL | C4: Accrual | D4: 12 | E4: Monthly 1 | F4: 12 | G4: Monthly 1 | I4: =COUNTA(D4:G4) -> 4 | J4: 3
B5: CL | C5: Applicable | D5: Joining | E5: Confirmation | F5: Joining | G5: Confirmation but accrual from joining | I5: =COUNTA(D5:G5) -> 4 | J5: 4
B6: CL | C6: Sandwich Applicable | D6: Yes | E6: No | F6: Yes | G6: No | I6: =COUNTA(D6:G6) -> 4 | J6: 4
B7: CL | C7: Min days for aplication | D7: 1 | E7: 3 | F7: NA | G7: NA | I7: =COUNTA(D7:G7) -> 4 | J7: 4
B8: CL | C8: Max Day for application | D8: NA | E8: NA | F8: 5 | G8: 1 | I8: =COUNTA(D8:G8) -> 4 | J8: 4
B9: CL | C9: No of application Monthly | D9: 4 | E9: 2 | F9: NA | G9: NA | I9: =COUNTA(D9:G9) -> 4 | J9: 3
B10: CL | C10: Max Days in Month | D10: NA | E10: NA | F10: 8 | G10: 4 | I10: =COUNTA(D10:G10) -> 4 | J10: 4
B11: CL | C11: Encashment/Lapse/CF | D11: Max Encash 10 remaining lapse | E11: Max CF 10 remaining lapse | F11: Encash 4,CF 3 remaining lapse | G11: No Encashment,No lapse | I11: =COUNTA(D11:G11) -> 4 | J11: 4
B12: CL | C12: Club with same day | D12: Yes | E12: No | F12: No | G12: Yes | I12: =COUNTA(D12:G12) -> 4 | J12: 3
B13: CL | C13: Club with another day | D13: No | E13: Yes | F13: Yes | G13: Yes | I13: =COUNTA(D13:G13) -> 4 | J13: 3
B14: CL | C14: Attachment Requirment | D14: More than 1 Day | E14: NA | F14: More than 3 Day | G14: NA | I14: =COUNTA(D14:G14) -> 4 | J14: 4
I15: =SUM(I3:I14) -> 48 | J15: =SUM(J3:J14) -> 44
B16: Note: | C16: Leave policy to be allocated based on location to employee

Sheet Payroll Configuration
A2: CTC salary calculation process
A3: STEP 1 | B3: Calculate the CTC for all employee from gross as mentioned in employee sheet with gratuity @ 4.81% and bonus @8.33%
A4: STEP 2 | B4: BASIC will be 40% of GROSS,HRA will be 25% of BASIC,MEDICAL Allowance will be 1000 fix for all employee and remaining amount will be calculated in other allowance
A5: STEP 3 | B5: Process 2 month payroll one with full attendance (Week off and Holiday) and another one with LOP for 5 days for Apr and May respectively
A6: STEP 4 | B6: Professional Tax to be calculated based on location available in employee category
A8: Payroll Evaluation
A9: COMPONENT | B9: WITH LOP | D9: WITHOUT LOP
B10: TARGET | C10: ACHIVEMENT | D10: TARGET | E10: ACHIVEMENT
A11: BASIC | B11: 40 | C11: 39 | D11: 40 | E11: 40
A12: HRA | B12: 40 | C12: 0 | D12: 40 | E12: 0 | G12: Wrong calculation
A13: MEDICAL | B13: 40 | C13: 39 | D13: 40 | E13: 40
A14: SPECIAL | B14: 40 | C14: 0 | D14: 40 | E14: 0 | G14: Wrong calculation
A15: PF | B15: 40 | C15: 0 | D15: 40 | E15: 0
A16: ESI | B16: 40 | C16: 0 | D16: 40 | E16: 0
A17: PT | B17: 40 | C17: 40 | D17: 40 | E17: 40
A18: Bonus Calculation and Provision | B18: 40 | C18: 36 | D18: 40 | E18: 32
A19: Gratuity Calculation and Provision | B19: 40 | C19: 0 | D19: 40 | E19: 0 | G19: Wrong calculation
A20: CTC | B20: 40 | C20: 0 | D20: 40 | E20: 0 | G20: Employer Contrubution for ESI not included,Bonus is incorrect
A21: TOTAL TARGET | C21: =SUM(B11:B20)+SUM(D11:D20) -> 800
A22: TOTAL ACHIVEMENT | C22: =SUM(C11:C20)+SUM(E11:E20) -> 306
A25: Improtant Note | B25: CTC needs to be calculated automatically based on gross upon configuration through payroll wizard hence direct upload through salary master for all component will not be counted

Sheet Evaluation Sheet
A1: Module | B1: Target | C1: Achived | D1: %
A2: Employee | B2: =Employee!M47 -> 440 | C2: =Employee!N47 -> 440 | D2: =ROUND(C2/B2*100,2) -> 100
A3: Attendance | B3: ='Attendance Configuration'!H22 -> 76 | C3: ='Attendance Configuration'!I22 -> 61 | D3: =ROUND(C3/B3*100,2) -> 80.26
A4: Leave | B4: ='[1]Leave Configuration'!G1 -> 48 | C4: ='Leave Configuration'!J15 -> 44 | D4: =ROUND(C4/B4*100,2) -> 91.67
A5: Payoll | B5: ='Payroll Configuration'!C21 -> 800 | C5: ='Payroll Configuration'!C22 -> 306 | D5: =ROUND(C5/B5*100,2) -> 38.25
A6: ACHIVEMENT | D6: =ROUND(SUM(D2:D5)/4,2) -> 77.55

Sheet Sheet2
A1: Cleared
A2: Not Cleared
A3: Partly Cleared
